Workbook

Sheet Data Quality Summary
A1: CRM Account Export - Data Quality Summary
A2: Greenline Retail | Cleaned for territory planning | Source: CRM Account Export tab (synthetic package cwk-sheets-033), read 2026-06-10
A4: Headline metrics
A5: Raw records exported | B5: =COUNTA('Raw Export'!A2:A81) -> 80
A6: Unique accounts after dedupe | B6: =COUNTA('Cleaned Accounts'!A2:A76) -> 75
A7: Duplicate records removed (merged into survivor) | B7: =COUNTA('Raw Export'!A2:A81)-COUNTA('Cleaned Accounts'!A2:A76) -> 5
A8: Raw book ARR (incl. duplicates) ($) | B8: =SUM('Raw Export'!G2:G81) -> 17952000
A9: Cleaned book ARR ($) | B9: =SUM('Cleaned Accounts'!F2:F76) -> 16938000
A10: ARR inflation from duplicate records ($) | B10: =B8-B9 -> 1014000
A11: Rows fully clean (no flags) | B11: =COUNTIF('Cleaned Accounts'!J2:J76,"OK") -> 45
A12: Rows needing RevOps attention | B12: =B6-B11 -> 30
A15: Issue register - fix before the territory model is locked
A16: ID | B16: Severity | C16: Issue | D16: Records | E16: Confidence | F16: Recommended action for RevOps
A17: DQ-1 | B17: High | C17: Region blank - account cannot be assigned to a territory | D17: =COUNTBLANK('Cleaned Accounts'!D2:D76) -> 14 | E17: n/a | F17: Backfill region from billing address or rep knowledge. Region is the territory dimension; the model cannot be locked while these are blank.
A18: DQ-2 | B18: High | C18: Region "US-East" does not fit the EMEA/APAC taxonomy and has no approved mapping | D18: =COUNTIF('Cleaned Accounts'!D2:D76,"US-East") -> 7 | E18: Medium | F18: Decide the Americas roll-up (e.g., add AMER) or keep sub-regions consistently. Normalization Map left the target blank, so this is a RevOps taxonomy decision, not a data fix.
A19: DQ-3 | B19: High | C19: Duplicate cluster: "Atlas Health, Inc." entered 6 times with conflicting ARR ($30K / $174K / $318K) and 5 different owners | D19: =COUNTIF('Raw Export'!B2:B81,"Atlas Health, Inc.") -> 6 | E19: Medium | F19: Survivor RAW-15072 kept (most recent, most complete); 5 records staged for merge on Duplicate Review tab. Confirm true ARR and owner with the source system before locking - do not trust the kept ARR.
A20: DQ-4 | B20: Medium | C20: Owner blank - account is unassigned | D20: =COUNTBLANK('Cleaned Accounts'!E2:E76) -> 6 | E20: n/a | F20: Assign owners before modeling rep capacity; unowned accounts skew territory load calculations.
A21: DQ-5 | B21: Medium | C21: Employees blank - missing firmographic used for segmentation | D21: =COUNTBLANK('Cleaned Accounts'!G2:G76) -> 7 | E21: n/a | F21: Enrich from a data provider or account research if employee count drives segment/tiering.
A22: DQ-6 | B22: High | C22: Source quality log warns a late-period definition/stage change may affect trend comparability (cwk-sheets-033-DQ-002) | D22: n/a | E22: n/a | F22: Confirm the ARR definition is consistent across the export window before using ARR trends to size territories.
A23: DQ-7 | B23: Low | C23: Industry misspelling "Hlthcare" - normalized to "Healthcare" per Normalization Map (resolved) | D23: =COUNTIF('Raw Export'!D2:D81,"Hlthcare") -> 8 | E23: High | F23: No action needed; fix applied. Add a picklist in the CRM to prevent recurrence.
A24: DQ-8 | B24: Low | C24: Source notes are directional; some judgment calls embedded in this cleanup (cwk-sheets-033-DQ-003) | D24: n/a | E24: n/a | F24: Treat Medium-confidence rows as provisional; assumptions listed on the Change Log tab.

Sheet Cleaned Accounts
A1: Account ID | B1: Account Name | C1: Industry | D1: Region | E1: Owner | F1: ARR ($) | G1: Employees | H1: Confidence | I1: Dedup Status | J1: Issue Flags
A2: RAW-15001 | B2: Redwood Labs 1 | C2: Retail | D2: EMEA | E2: Jon Bell | F2: 54000 | G2: 108 | H2: High | I2: Unique | J2: OK
A3: RAW-15002 | B3: CivicGrid 2 | C3: Finance | D3: APAC | E3: Priya Nair | F3: 78000 | G3: 116 | H3: High | I3: Unique | J3: OK
A4: RAW-15003 | B4: Atlas Health 3 | C4: Public Sector | E4: Sam Ortiz | F4: 102000 | G4: 124 | H4: High | I4: Unique | J4: Missing region
A5: RAW-15004 | B5: Greenline Retail 4 | C5: Healthcare | D5: EMEA | E5: Lee Kim | F5: 126000 | G5: 132 | H5: High | I5: Unique | J5: OK
A6: RAW-15005 | B6: FlowOps 5 | C6: Retail | D6: APAC | E6: Nora Patel | F6: 150000 | G6: 140 | H6: High | I6: Unique | J6: OK
A7: RAW-15006 | B7: Northstar Apps 6 | C7: Finance | E7: Alex Rivera | F7: 174000 | G7: 148 | H7: High | I7: Unique | J7: Missing region
A8: RAW-15007 | B8: Redwood Labs 7 | C8: Public Sector | D8: EMEA | E8: Dana Brooks | F8: 198000 | G8: 156 | H8: High | I8: Unique | J8: OK
A9: RAW-15008 | B9: CivicGrid 8 | C9: Healthcare | D9: APAC | E9: Iris Stone | F9: 222000 | G9: 164 | H9: High | I9: Unique | J9: OK
A10: RAW-15009 | B10: Atlas Health 9 | C10: Retail | D10: US-East | E10: Theo Grant | F10: 246000 | G10: 172 | H10: Medium | I10: Unique | J10: Unmapped region (US-East)
A11: RAW-15010 | B11: Greenline Retail 10 | C11: Healthcare | D11: EMEA | E11: Maya Chen | F11: 270000 | G11: 180 | H11: High | I11: Unique | J11: OK
A12: RAW-15011 | B12: FlowOps 11 | C12: Public Sector | D12: APAC | E12: Jon Bell | F12: 294000 | H12: High | I12: Unique | J12: Missing employees
A13: RAW-15013 | B13: Redwood Labs 13 | C13: Retail | D13: EMEA | F13: 342000 | G13: 204 | H13: High | I13: Unique | J13: Missing owner
A14: RAW-15014 | B14: CivicGrid 14 | C14: Finance | D14: APAC | E14: Lee Kim | F14: 366000 | G14: 212 | H14: High | I14: Unique | J14: OK
A15: RAW-15015 | B15: Atlas Health 15 | C15: Public Sector | E15: Nora Patel | F15: 390000 | G15: 220 | H15: High | I15: Unique | J15: Missing region
A16: RAW-15016 | B16: Greenline Retail 16 | C16: Healthcare | D16: EMEA | E16: Alex Rivera | F16: 414000 | G16: 228 | H16: High | I16: Unique | J16: OK
A17: RAW-15017 | B17: FlowOps 17 | C17: Retail | D17: APAC | E17: Dana Brooks | F17: 438000 | G17: 236 | H17: High | I17: Unique | J17: OK
A18: RAW-15018 | B18: Northstar Apps 18 | C18: Finance | D18: US-East | E18: Iris Stone | F18: 30000 | G18: 244 | H18: Medium | I18: Unique | J18: Unmapped region (US-East)
A19: RAW-15019 | B19: Redwood Labs 19 | C19: Public Sector | D19: EMEA | E19: Theo Grant | F19: 54000 | G19: 252 | H19: High | I19: Unique | J19: OK
A20: RAW-15020 | B20: CivicGrid 20 | C20: Healthcare | D20: APAC | E20: Maya Chen | F20: 78000 | G20: 260 | H20: High | I20: Unique | J20: OK
A21: RAW-15021 | B21: Atlas Health 21 | C21: Retail | E21: Jon Bell | F21: 102000 | G21: 268 | H21: High | I21: Unique | J21: Missing region
A22: RAW-15022 | B22: Greenline Retail 22 | C22: Finance | D22: EMEA | E22: Priya Nair | F22: 126000 | H22: High | I22: Unique | J22: Missing employees
A23: RAW-15023 | B23: FlowOps 23 | C23: Public Sector | D23: APAC | E23: Sam Ortiz | F23: 150000 | G23: 284 | H23: High | I23: Unique | J23: OK
A24: RAW-15025 | B24: Redwood Labs 25 | C24: Retail | D24: EMEA | E24: Nora Patel | F24: 198000 | G24: 300 | H24: High | I24: Unique | J24: OK
A25: RAW-15026 | B25: CivicGrid 26 | C25: Finance | D25: APAC | F25: 222000 | G25: 308 | H25: High | I25: Unique | J25: Missing owner
A26: RAW-15027 | B26: Atlas Health 27 | C26: Public Sector | D26: US-East | E26: Dana Brooks | F26: 246000 | G26: 316 | H26: Medium | I26: Unique | J26: Unmapped region (US-East)
A27: RAW-15028 | B27: Greenline Retail 28 | C27: Healthcare | D27: EMEA | E27: Iris Stone | F27: 270000 | G27: 324 | H27: High | I27: Unique | J27: OK
A28: RAW-15029 | B28: FlowOps 29 | C28: Retail | D28: APAC | E28: Theo Grant | F28: 294000 | G28: 332 | H28: High | I28: Unique | J28: OK
A29: RAW-15030 | B29: Northstar Apps 30 | C29: Healthcare | E29: Maya Chen | F29: 318000 | G29: 340 | H29: High | I29: Unique | J29: Missing region
A30: RAW-15031 | B30: Redwood Labs 31 | C30: Public Sector | D30: EMEA | E30: Jon Bell | F30: 342000 | G30: 348 | H30: High | I30: Unique | J30: OK
A31: RAW-15032 | B31: CivicGrid 32 | C31: Healthcare | D31: APAC | E31: Priya Nair | F31: 366000 | G31: 356 | H31: High | I31: Unique | J31: OK
A32: RAW-15033 | B32: Atlas Health 33 | C32: Retail | E32: Sam Ortiz | F32: 390000 | H32: High | I32: Unique | J32: Missing region; Missing employees
A33: RAW-15034 | B33: Greenline Retail 34 | C33: Finance | D33: EMEA | E33: Lee Kim | F33: 414000 | G33: 372 | H33: High | I33: Unique | J33: OK
A34: RAW-15035 | B34: FlowOps 35 | C34: Public Sector | D34: APAC | E34: Nora Patel | F34: 438000 | G34: 380 | H34: High | I34: Unique | J34: OK
A35: RAW-15037 | B35: Redwood Labs 37 | C35: Retail | D35: EMEA | E35: Dana Brooks | F35: 54000 | G35: 396 | H35: High | I35: Unique | J35: OK
A36: RAW-15038 | B36: CivicGrid 38 | C36: Finance | D36: APAC | E36: Iris Stone | F36: 78000 | G36: 404 | H36: High | I36: Unique | J36: OK
A37: RAW-15039 | B37: Atlas Health 39 | C37: Public Sector | F37: 102000 | G37: 412 | H37: High | I37: Unique | J37: Missing region; Missing owner
A38: RAW-15040 | B38: Greenline Retail 40 | C38: Healthcare | D38: EMEA | E38: Maya Chen | F38: 126000 | G38: 420 | H38: High | I38: Unique | J38: OK
A39: RAW-15041 | B39: FlowOps 41 | C39: Retail | D39: APAC | E39: Jon Bell | F39: 150000 | G39: 428 | H39: High | I39: Unique | J39: OK
A40: RAW-15042 | B40: Northstar Apps 42 | C40: Finance | E40: Priya Nair | F40: 174000 | G40: 436 | H40: High | I40: Unique | J40: Missing region
...

Sheet Duplicate Review
A1: Duplicate group DG-1: "Atlas Health, Inc." (6 raw records, 1 account)
A2: Match basis: identical account name; all normalize to "Atlas Health" (Normalization Map confidence: Medium). Conflicting ARR and owners mean merge is NOT safe to automate - confirm with source before locking.
A4: Group | B4: Raw ID | C4: Account Name | D4: Industry (raw) | E4: Region | F4: Owner | G4: ARR ($) | H4: Employees | I4: Match Confidence | J4: Disposition
A5: DG-1 | B5: RAW-15012 | C5: Atlas Health, Inc. | D5: Healthcare | F5: Priya Nair | G5: 318000 | H5: 196 | I5: Medium | J5: MERGE into RAW-15072 - pending review
A6: DG-1 | B6: RAW-15024 | C6: Atlas Health, Inc. | D6: Healthcare | F6: Lee Kim | G6: 174000 | H6: 292 | I6: Medium | J6: MERGE into RAW-15072 - pending review
A7: DG-1 | B7: RAW-15036 | C7: Atlas Health, Inc. | D7: Healthcare | E7: US-East | F7: Alex Rivera | G7: 30000 | H7: 388 | I7: Medium | J7: MERGE into RAW-15072 - pending review
A8: DG-1 | B8: RAW-15048 | C8: Atlas Health, Inc. | D8: Healthcare | F8: Iris Stone | G8: 318000 | H8: 484 | I8: Medium | J8: MERGE into RAW-15072 - pending review
A9: DG-1 | B9: RAW-15060 | C9: Atlas Health, Inc. | D9: Hlthcare | F9: Maya Chen | G9: 174000 | H9: 580 | I9: Medium | J9: MERGE into RAW-15072 - pending review
A10: DG-1 | B10: RAW-15072 | C10: Atlas Health, Inc. | D10: Healthcare | E10: US-East | F10: Priya Nair | G10: 30000 | H10: 676 | I10: Medium | J10: KEEP - survivor (most recent, most complete)
A12: Conflicts to resolve before merge
A13: ARR | B13: Three different values across the group: $30,000 / $174,000 / $318,000 (each appears twice). True ARR unknown - verify in billing.
A14: Owner | B14: 5 distinct owners across 6 records (Priya Nair x2, Lee Kim, Alex Rivera, Iris Stone, Maya Chen). Assign one owner.
A15: Region | B15: Blank on 4 of 6 records; US-East on 2. US-East itself is an unmapped value (see DQ-2).
A16: Employees | B16: Ranges 196-676 across records; survivor value 676 retained provisionally.
A17: Survivor rule | B17: Highest Raw ID kept as most recent record (assumption - no created/modified date in export).

Sheet Normalization Log
A1: Normalization applied (per Normalization Map tab in source)
A3: Field | B3: Raw Value | C3: Normalized To | D3: Rows Affected | E3: Confidence | F3: Status
A4: Industry | B4: Hlthcare | C4: Healthcare | D4: =COUNTIF('Raw Export'!D2:D81,"Hlthcare") -> 8 | E4: High | F4: APPLIED - deterministic misspelling fix
A5: Account Name | B5: Atlas Health, Inc. | C5: Atlas Health | D5: =COUNTIF('Raw Export'!B2:B81,"Atlas Health, Inc.") -> 6 | E5: Medium | F5: APPLIED to naming; merge staged on Duplicate Review - needs sign-off
A6: Region | B6: US-East | C6: (no approved mapping) | D6: =COUNTIF('Raw Export'!E2:E81,"US-East") -> 8 | E6: Medium | F6: NOT APPLIED - value kept and flagged; RevOps must define the Americas taxonomy
A7: Region | B7: (blank) | C7: (cannot infer) | D7: =COUNTBLANK('Raw Export'!E2:E81) -> 18 | E7: n/a | F7: NOT APPLIED - missing data, flagged for backfill
A9: Resulting Industry distribution (cleaned)
A10: Industry | B10: Accounts
A11: Healthcare | B11: =COUNTIF('Cleaned Accounts'!C2:C76,"Healthcare") -> 19
A12: Retail | B12: =COUNTIF('Cleaned Accounts'!C2:C76,"Retail") -> 20
A13: Public Sector | B13: =COUNTIF('Cleaned Accounts'!C2:C76,"Public Sector") -> 20
A14: Finance | B14: =COUNTIF('Cleaned Accounts'!C2:C76,"Finance") -> 16
A15: Total | B15: =SUM(B11:B14) -> 75
A17: Resulting Region distribution (cleaned)
A18: Region | B18: Accounts
A19: EMEA | B19: =COUNTIF('Cleaned Accounts'!D2:D76,"EMEA") -> 27
A20: APAC | B20: =COUNTIF('Cleaned Accounts'!D2:D76,"APAC") -> 27
A21: US-East (unmapped) | B21: =COUNTIF('Cleaned Accounts'!D2:D76,"US-East") -> 7
A22: (blank) | B22: =COUNTBLANK('Cleaned Accounts'!D2:D76) -> 14
A23: Total | B23: =SUM(B19:B22) -> 75

Sheet Raw Export
A1: Raw ID | B1: Account Name | C1: Normalized Account | D1: Industry | E1: Region | F1: Owner | G1: ARR | H1: Employees | I1: Match Confidence | J1: Cleanup Flag
A2: RAW-15001 | B2: Redwood Labs 1 | C2: Redwood Labs 1 | D2: Retail | E2: EMEA | F2: Jon Bell | G2: 54000 | H2: 108 | I2: High | J2: OK
A3: RAW-15002 | B3: CivicGrid 2 | C3: CivicGrid 2 | D3: Finance | E3: APAC | F3: Priya Nair | G3: 78000 | H3: 116 | I3: High | J3: OK
A4: RAW-15003 | B4: Atlas Health 3 | C4: Atlas Health 3 | D4: Public Sector | F4: Sam Ortiz | G4: 102000 | H4: 124 | I4: High | J4: OK
A5: RAW-15004 | B5: Greenline Retail 4 | C5: Greenline Retail 4 | D5: Healthcare | E5: EMEA | F5: Lee Kim | G5: 126000 | H5: 132 | I5: High | J5: OK
A6: RAW-15005 | B6: FlowOps 5 | C6: FlowOps 5 | D6: Retail | E6: APAC | F6: Nora Patel | G6: 150000 | H6: 140 | I6: High | J6: OK
A7: RAW-15006 | B7: Northstar Apps 6 | C7: Northstar Apps 6 | D7: Finance | F7: Alex Rivera | G7: 174000 | H7: 148 | I7: High | J7: OK
A8: RAW-15007 | B8: Redwood Labs 7 | C8: Redwood Labs 7 | D8: Public Sector | E8: EMEA | F8: Dana Brooks | G8: 198000 | H8: 156 | I8: High | J8: OK
A9: RAW-15008 | B9: CivicGrid 8 | C9: CivicGrid 8 | D9: Healthcare | E9: APAC | F9: Iris Stone | G9: 222000 | H9: 164 | I9: High | J9: OK
A10: RAW-15009 | B10: Atlas Health 9 | C10: Atlas Health 9 | D10: Retail | E10: US-East | F10: Theo Grant | G10: 246000 | H10: 172 | I10: High | J10: OK
A11: RAW-15010 | B11: Greenline Retail 10 | C11: Greenline Retail 10 | D11: Hlthcare | E11: EMEA | F11: Maya Chen | G11: 270000 | H11: 180 | I11: High | J11: Normalize industry
A12: RAW-15011 | B12: FlowOps 11 | C12: FlowOps 11 | D12: Public Sector | E12: APAC | F12: Jon Bell | G12: 294000 | I12: High | J12: OK
A13: RAW-15012 | B13: Atlas Health, Inc. | C13: Atlas Health | D13: Healthcare | F13: Priya Nair | G13: 318000 | H13: 196 | I13: Medium | J13: Possible duplicate
A14: RAW-15013 | B14: Redwood Labs 13 | C14: Redwood Labs 13 | D14: Retail | E14: EMEA | G14: 342000 | H14: 204 | I14: High | J14: Missing owner
A15: RAW-15014 | B15: CivicGrid 14 | C15: CivicGrid 14 | D15: Finance | E15: APAC | F15: Lee Kim | G15: 366000 | H15: 212 | I15: High | J15: OK
A16: RAW-15015 | B16: Atlas Health 15 | C16: Atlas Health 15 | D16: Public Sector | F16: Nora Patel | G16: 390000 | H16: 220 | I16: High | J16: OK
A17: RAW-15016 | B17: Greenline Retail 16 | C17: Greenline Retail 16 | D17: Healthcare | E17: EMEA | F17: Alex Rivera | G17: 414000 | H17: 228 | I17: High | J17: OK
A18: RAW-15017 | B18: FlowOps 17 | C18: FlowOps 17 | D18: Retail | E18: APAC | F18: Dana Brooks | G18: 438000 | H18: 236 | I18: High | J18: OK
A19: RAW-15018 | B19: Northstar Apps 18 | C19: Northstar Apps 18 | D19: Finance | E19: US-East | F19: Iris Stone | G19: 30000 | H19: 244 | I19: High | J19: OK
A20: RAW-15019 | B20: Redwood Labs 19 | C20: Redwood Labs 19 | D20: Public Sector | E20: EMEA | F20: Theo Grant | G20: 54000 | H20: 252 | I20: High | J20: OK
A21: RAW-15020 | B21: CivicGrid 20 | C21: CivicGrid 20 | D21: Hlthcare | E21: APAC | F21: Maya Chen | G21: 78000 | H21: 260 | I21: High | J21: Normalize industry
A22: RAW-15021 | B22: Atlas Health 21 | C22: Atlas Health 21 | D22: Retail | F22: Jon Bell | G22: 102000 | H22: 268 | I22: High | J22: OK
A23: RAW-15022 | B23: Greenline Retail 22 | C23: Greenline Retail 22 | D23: Finance | E23: EMEA | F23: Priya Nair | G23: 126000 | I23: High | J23: OK
A24: RAW-15023 | B24: FlowOps 23 | C24: FlowOps 23 | D24: Public Sector | E24: APAC | F24: Sam Ortiz | G24: 150000 | H24: 284 | I24: High | J24: OK
A25: RAW-15024 | B25: Atlas Health, Inc. | C25: Atlas Health | D25: Healthcare | F25: Lee Kim | G25: 174000 | H25: 292 | I25: Medium | J25: Possible duplicate
A26: RAW-15025 | B26: Redwood Labs 25 | C26: Redwood Labs 25 | D26: Retail | E26: EMEA | F26: Nora Patel | G26: 198000 | H26: 300 | I26: High | J26: OK
A27: RAW-15026 | B27: CivicGrid 26 | C27: CivicGrid 26 | D27: Finance | E27: APAC | G27: 222000 | H27: 308 | I27: High | J27: Missing owner
A28: RAW-15027 | B28: Atlas Health 27 | C28: Atlas Health 27 | D28: Public Sector | E28: US-East | F28: Dana Brooks | G28: 246000 | H28: 316 | I28: High | J28: OK
A29: RAW-15028 | B29: Greenline Retail 28 | C29: Greenline Retail 28 | D29: Healthcare | E29: EMEA | F29: Iris Stone | G29: 270000 | H29: 324 | I29: High | J29: OK
A30: RAW-15029 | B30: FlowOps 29 | C30: FlowOps 29 | D30: Retail | E30: APAC | F30: Theo Grant | G30: 294000 | H30: 332 | I30: High | J30: OK
A31: RAW-15030 | B31: Northstar Apps 30 | C31: Northstar Apps 30 | D31: Hlthcare | F31: Maya Chen | G31: 318000 | H31: 340 | I31: High | J31: Normalize industry
A32: RAW-15031 | B32: Redwood Labs 31 | C32: Redwood Labs 31 | D32: Public Sector | E32: EMEA | F32: Jon Bell | G32: 342000 | H32: 348 | I32: High | J32: OK
A33: RAW-15032 | B33: CivicGrid 32 | C33: CivicGrid 32 | D33: Healthcare | E33: APAC | F33: Priya Nair | G33: 366000 | H33: 356 | I33: High | J33: OK
A34: RAW-15033 | B34: Atlas Health 33 | C34: Atlas Health 33 | D34: Retail | F34: Sam Ortiz | G34: 390000 | I34: High | J34: OK
A35: RAW-15034 | B35: Greenline Retail 34 | C35: Greenline Retail 34 | D35: Finance | E35: EMEA | F35: Lee Kim | G35: 414000 | H35: 372 | I35: High | J35: OK
A36: RAW-15035 | B36: FlowOps 35 | C36: FlowOps 35 | D36: Public Sector | E36: APAC | F36: Nora Patel | G36: 438000 | H36: 380 | I36: High | J36: OK
A37: RAW-15036 | B37: Atlas Health, Inc. | C37: Atlas Health | D37: Healthcare | E37: US-East | F37: Alex Rivera | G37: 30000 | H37: 388 | I37: Medium | J37: Possible duplicate
A38: RAW-15037 | B38: Redwood Labs 37 | C38: Redwood Labs 37 | D38: Retail | E38: EMEA | F38: Dana Brooks | G38: 54000 | H38: 396 | I38: High | J38: OK
A39: RAW-15038 | B39: CivicGrid 38 | C39: CivicGrid 38 | D39: Finance | E39: APAC | F39: Iris Stone | G39: 78000 | H39: 404 | I39: High | J39: OK
A40: RAW-15039 | B40: Atlas Health 39 | C40: Atlas Health 39 | D40: Public Sector | G40: 102000 | H40: 412 | I40: High | J40: Missing owner
...

Sheet Change Log
A1: Range Read | B1: Rows Changed | C1: Formula Added | D1: Assumption | E1: Manual Review
A2: CRM Account Export!A:J (80 records) | B2: 8 industry values normalized; 5 duplicate records merged out (80 -> 75); 30 cleaned rows carry at least one issue flag | C2: COUNTIF / COUNTBLANK / SUM metrics on Data Quality Summary and Normalization Log recompute from Raw Export and Cleaned Accounts | D2: Survivor for the Atlas Health duplicate group = highest Raw ID (RAW-15072), used as recency proxy because the export has no created/modified date; US-East kept as-is pending taxonomy decision | E2: Medium-confidence items requiring sign-off: Atlas Health merge (conflicting ARR/owner) and US-East region mapping; plus backfill of blank Region (14), Owner (6), Employees (7) in cleaned data
